Workbook

Sheet B2B
A1: Sr. No. | B1: Type of Order(New/Upgrade) | C1: RA Number | E1: GTPL Circuit ID | F1: Customer Name | G1: BW | H1: Provider | I1: Services | J1: Location From | K1: Location To | L1: State | M1: END A BTS ID | N1: END B BTS ID | O1: Indent Number | P1: RA Received Date | Q1: RA Number | R1: END A Port | S1: END B Port | T1: IP Address | U1: Subnet | V1: Gateway | W1: LAN IP POOL | X1: IPV6 LAN IP Pool | Y1: VLAN / AS number | Z1: TELCO Delivery Date | AA1: Customer Billing Start Date | AB1: TELCO Acceptance Date | AC1: GTPL Circuit ID | AD1: AIRTEL Circuit ID | AE1: Remarks | AF1: Existing BW | AG1: NEW BW | AH1: Additional BW | AI1: Order closer date | AJ1: Status | AK1: DC Date
A2: 1 | B2: New | C2: 3230043 | E2: GTPL_MUM_33905 | F2: Trueinet Network | G2: 100 | H2: AIRTEL | I2: P2P | J2: Mumbai | K2: Palghar | M2: MUM/XVS/901 | N2: MPO/OBT/001 | Q2: 3230043 | R2: END A:MUM_XVS_901_10AC Port : GigabitEthernet0/2/9 VLAN : 190 | S2: END B:MPO_BCLMH_OBT_P_E53143 Port : TS6-4 | T2: NA | U2: NA | V2: NA | W2: NA | X2: NA | Y2: 190 | Z2: 43755 | AB2: 43774 | AC2: GTPL_MUM_33905 | AD2: 13273408 | AJ2: Inactive
A3: 2 | B3: New | C3: 3218818 | E3: GTPL_MUM_33910 | F3: Trueinet Network | G3: 250 | H3: AIRTEL | I3: P2P | J3: Mumbai | K3: Dhanu | M3: MUM/XVS/901 | N3: DUT/DCR/001 | Q3: 3218818 | R3: MUM_XVS_901_10AC_B_HAT910CR157-GigabitEthernet0/2/9 | S3: END B : DUT_BCLMH_DCR_P_E51175 TS4-1 | T3: NA | U3: NA | V3: NA | W3: NA | X3: NA | Y3: 109 | Z3: 43775 | AB3: 43776 | AC3: GTPL_MUM_33910 | AD3: 13262568 | AJ3: Inactive
A4: 3 | B4: New | C4: 3218823 | E4: GTPL_MUM_33911 | F4: Trueinet Network | G4: 155 | H4: AIRTEL | I4: P2P | J4: Mumbai | K4: Palghar | M4: MUM/XVS/901 | N4: PGR/ATK/004 | Q4: 3218823 | R4: END A : MUM_XVS_901_10AC_B_HAT910CR157-GigabitEthernet0/2/9 | S4: END B : PGR_BCLMH_ATK_P_E55903 TS3-1 | T4: NA | U4: NA | V4: NA | W4: NA | X4: NA | Y4: 106 | Z4: 43785 | AB4: 43785 | AC4: GTPL_MUM_33911 | AD4: 13263934 | AJ4: Inactive
A5: 4 | B5: New | C5: 3218816 | E5: GTPL_MUM_33916 | F5: Trueinet Network | G5: 250 | H5: AIRTEL | I5: P2P | J5: Mumbai | K5: Palghar | M5: MUM/XVS/901 | N5: PBR/BGN/012 | Q5: 3218816 | R5: MUM_XVS_901_10AC_B_HAT910CR157>dis curr int G0/2/9.VLAN-104 | S5: TAA_BCLMH_BGN_P_E89979 TS1-1 | T5: NA | U5: NA | V5: NA | W5: NA | X5: NA | Y5: 104 | Z5: 43802 | AB5: 43802 | AC5: GTPL_MUM_33916 | AD5: 13262482 | AJ5: Inactive
A6: 5 | B6: New | C6: 3279746 | E6: GTPL_MUM_33917 | F6: Trueinet Network | G6: 100 | H6: AIRTEL | I6: P2P | J6: Mumbai | K6: Dahanu | M6: MUM/XVS/901 | N6: THN/CHN/058 | Q6: 3279746 | R6: MUM_XVS_901_10AC_B_HAT910CR157>dis cu in GigabitEthernet0/2/9 | S6: THN_BCLMH_CHN_P_E51174 TS7-3 | T6: NA | U6: NA | V6: NA | W6: NA | X6: NA | Y6: 107 | Z6: 43830 | AB6: 43811 | AC6: GTPL_MUM_33917 | AD6: 13330609 | AJ6: Inactive
A7: 6 | B7: New | C7: 3716416 | E7: GTPL_P2P_10101 | F7: ARROW TOUCH WIRELESS INTERNET PRIVATE LIMTED | G7: 50 | H7: Airtel | I7: P2P | J7: Jasdan | K7: Kuranga | L7: Gujarat | M7: JDN/MCP/003 | N7: KUG/JOH/001 | Q7: 3716416 | R7: JDN_BCLGJ_MCP_P_E91271 TS7-4 VLAN 1104 | S7: KUG_BCLGJ_JOH_P_E52163 TS7-2 | T7: NA | U7: NA | V7: NA | W7: NA | X7: NA | Y7: 1104 | Z7: 44226 | AB7: 44227 | AC7: GTPL_P2P_10101 | AD7: 13831356 | AJ7: Active
A8: 7 | B8: New | C8: 3716415 | E8: GTPL_P2P_10102 | F8: ARROW TOUCH WIRELESS INTERNET PRIVATE LIMTED | G8: 80 | H8: Airtel | I8: P2P | J8: Jasdan | K8: Mundra | L8: Gujarat | M8: JDN/MCP/003 | N8: VKP/NSP/001 | Q8: 3716415 | R8: JDN_BCLGJ_MCP_P_E91271 NNI TS7-4 VLAN:786 | S8: VKP_BCLGJ_NSP_P_E52197 TS2-4 | T8: NA | U8: NA | V8: NA | W8: NA | X8: NA | Y8: 786 | Z8: 44226 | AB8: 44227 | AC8: GTPL_P2P_10102 | AD8: 13831357 | AJ8: Active
A9: 8 | B9: New + Upgrade | C9: 3703843 | E9: GTPL_P2P_10103 | F9: ARROW TOUCH WIRELESS INTERNET PRIVATE LIMTED | G9: 100 | H9: Airtel | I9: P2P | J9: Jasdan | K9: Jamjodhpur | L9: Gujarat | M9: JDN/MCP/003 | N9: JJO/NSM/001 | Q9: 3703843 | R9: JDN_BCLGJ_MCP_P_E91271 TS7-4 VLAN 1101 | S9: JJO_BCLGJ_NSM_P_E52172 TS6-2 | T9: NA | U9: NA | V9: NA | W9: NA | X9: NA | Y9: 1101 | Z9: 44226 | AB9: 44227 | AC9: GTPL_P2P_10103 | AD9: 13801004 | AF9: 80 | AG9: 100 | AH9: 20 | AI9: 44487 | AJ9: Active
A10: 9 | B10: New | C10: 3703842 | E10: GTPL_P2P_10104 | F10: ARROW TOUCH WIRELESS INTERNET PRIVATE LIMTED | G10: 80 | H10: Airtel | I10: P2P | J10: Jasdan | K10: Khambhaliya | L10: Gujarat | M10: JDN/MCP/003 | N10: KBL/OPP/001 | Q10: 3703842 | R10: JDN_BCLGJ_MCP_P_E91271 TS7-4 VLAN 1102 | S10: KBL_BCLGJ_OPP_P_E97780 TS1-P1 | T10: NA | U10: NA | V10: NA | W10: NA | X10: NA | Y10: 1102 | Z10: 44226 | AB10: 44227 | AC10: GTPL_P2P_10104 | AD10: 13801031 | AJ10: Inactive | AK10: 44637
A11: 10 | B11: New | C11: 3736919 | F11: GTPL BROADBAND PVT LTD(Enterprise) | G11: 50 | H11: Airtel | I11: P2M | J11: Baroda | K11: Manjusar | L11: Gujarat | M11: BRD/NWT/107 | N11: VDD/SVL/009 | Q11: 3736919 | R11: BRD_GTPGJ_NWT_P_E97732 - XSA-3 -- VLAN – 1550 | S11: VDD_BCLGJ_SVL_P_E87315 TS1-4 | T11: NA | U11: NA | V11: NA | W11: NA | X11: NA | Y11: 1550 | Z11: 44249 | AB11: 44251 | AC11: NA | AD11: 13852522 | AJ11: Active
A12: 11 | B12: New | C12: 3725714 | E12: GTPL_JPR_55081 | F12: ISPARROW DIGITAL PVT LTD | G12: 750 | H12: Airtel | I12: ILL | J12: NA | K12: Jaipur | L12: Rajasthan | M12: NA | N12: JPR/JMA/901 | Q12: 3725714 | R12: NA | S12: JPR_JMA_901_2AC_M_ASASMXPR014# configure port 1/1/12 | T12: 125.22.82.34 | U12: 255.255.255.252 | V12: 125.22.82.33 | W12: 125.18.53.224/29, 103.125.76.0/22 | X12: NA | Y12: NA | Z12: 44259 | AB12: 44258 | AC12: GTPL_JPR_55081 | AD12: 13840211 | AJ12: Active | AK12: 44868
A13: 12 | B13: New | C13: 3725709 | E13: GTPL_JPR_10101 | F13: ISPARROW DIGITAL PVT LTD | G13: 300 | H13: Airtel | I13: P2P | J13: Jaipur | K13: Mahapura | L13: Rajasthan | M13: JPR/JMA/901 | N13: JPR/JMP/901 | Q13: 3725709 | R13: JPR_JMA_901_1AC_ASAR8XXR014 1/1/5 VLAN-101 | S13: JPR_JMP_901_2AC_M_ASASMXPR055# configure port 1/1/4 | T13: NA | U13: NA | V13: NA | W13: NA | X13: NA | Y13: 101 | Z13: 44266 | AB13: 44266 | AC13: GTPL_JPR_10101 | AD13: 13840227 | AJ13: Active | AK13: 44868
A14: 13 | B14: New | C14: 3725707 | E14: GTPL_JPR_10102 | F14: ISPARROW DIGITAL PVT LTD | G14: 100 | H14: Airtel | I14: P2P | J14: Jaipur | K14: VDN | L14: Rajasthan | M14: JPR/JMA/901 | N14: JPR/JVR/901 | Q14: 3725707 | R14: JPR_JMA_901_1AC_ASAR8XXR014 1/1/5:102 | S14: JPR_JVR_901_1AC_M_ASAR8XXR019 Port 1/2/1 | T14: NA | U14: NA | V14: NA | W14: NA | X14: NA | Y14: 101 | Z14: 44266 | AB14: 44266 | AC14: GTPL_JPR_10102 | AD14: 13840224 | AJ14: Inactive | AK14: 44814
A15: 14 | B15: New | C15: 3725706 | E15: GTPL_JPR_10103 | F15: ISPARROW DIGITAL PVT LTD | G15: 50 | H15: Airtel | I15: P2P | J15: Jaipur | K15: Syari Mod | L15: Rajasthan | M15: JPR/JMA/901 | N15: TLX/JRD/001 | Q15: 3725706 | R15: JPR_JMA_901_1AC_ASAR8XXR014 1/1/5:149 | S15: TLX_BCLRJ_JRD_P_E56116 TS6-1 | T15: NA | U15: NA | V15: NA | W15: NA | X15: NA | Y15: 149 | Z15: 44266 | AB15: 44266 | AC15: GTPL_JPR_10103 | AD15: 13840221 | AJ15: Active | AK15: 44868
A16: 15 | B16: New | C16: 3725710 | E16: GTPL_JPR_10105 | F16: ISPARROW DIGITAL PVT LTD | G16: 155 | H16: Airtel | I16: P2P | J16: Jaipur | K16: Kanota | L16: Rajasthan | M16: JPR/JMA/901 | N16: JPR/KTA/080 | Q16: 3725710 | R16: JPR_JMA_901_1AC_ASAR8XXR014 1/1/5:104 | S16: JPR_BCLRJ_KTA_P_E86128 TS1-2 | T16: NA | U16: NA | V16: NA | W16: NA | X16: NA | Y16: 104 | Z16: 44266 | AB16: 44266 | AC16: GTPL_JPR_10105 | AD16: 13840226 | AJ16: Active | AK16: 44868
A17: 16 | B17: New | C17: 3725708 | E17: GTPL_JPR_10104 | F17: ISPARROW DIGITAL PVT LTD | G17: 50 | H17: Airtel | I17: P2P | J17: Jaipur | K17: Raja Park | L17: Rajasthan | M17: JPR/JMA/901 | N17: JPR/JGR/901 | Q17: 3725708 | R17: JPR_JMA_901_1AC_ASAR8XXR014 1/1/5 VLAN-100 | S17: JPR_JGR_901_1AC_M_ASAR8XXR037 Port 1/5/3 | T17: NA | U17: NA | V17: NA | W17: NA | X17: NA | Y17: 100 | Z17: 44266 | AB17: 44266 | AC17: GTPL_JPR_10104 | AD17: 13840223 | AJ17: Inactive
A18: 17 | B18: New + Downgrade | C18: 3763746 | E18: GTPL_JPR_10201 | F18: Royal Connect Solutions Pvt Ltd | G18: 500 | H18: Airtel | I18: ILL | J18: NA | K18: Jaipur | L18: Rajasthan | M18: NA | N18: JPR/JMA/902 | Q18: 3763746 | R18: NA | S18: JPR_RSW_901_1AC_M_ASAR8XXR009#1/6/5 | T18: 122.186.83.130 | U18: 255.255.255.252 | V18: 122.186.83.129 | W18: 103.118.168.0/22 | X18: NA | Y18: NA | Z18: 44272 | AB18: 44271 | AC18: GTPL_JPR_10201 | AD18: 13874456 | AF18: 1000 | AG18: 500 | AH18: -500 | AI18: 44667 | AJ18: Active
A19: 18 | B19: New | C19: 3730217 | E19: GTPL_APL_10102 | F19: CENTUM TAX PVT LTD | G19: 100 | H19: Airtel | I19: P2P | J19: Hyderabad | K19: Hyderabad | L19: Telangana | M19: HYD/UPL/920 | N19: HYD/MPT/917 | Q19: 3730217 | R19: HYD_UPL_920_5AC_B_IXREXXR572# sap 1/1/4:201 | S19: HYD/MPT/917 Port : 1/1/2 | T19: NA | U19: NA | V19: NA | W19: NA | X19: NA | Y19: 201 | Z19: 44278 | AB19: 44278 | AC19: GTPL_APL_10102 | AD19: 13845110 | AJ19: Active
A20: 19 | B20: New | C20: 3763798 | E20: GTPL_RJT_10202 | F20: Vision Hi-Speed Technology Pvt. Ltd | G20: 45 | H20: Airtel | I20: P2P | J20: Rajkot | K20: Sarangpur | L20: Gujarat | M20: RKT/NSS/032 | N20: BTQ/SAL/005 | Q20: 3763798 | R20: RKT/NSS/032 RKT_BCLGJ_NSS_P_E51932 TS4-2 | S20: BTQ/SAL/005 BTQ_BCLGJ_SAL_P_E59415 TS1-3 | T20: NA | U20: NA | V20: NA | W20: NA | X20: NA | Z20: 44285 | AB20: 44285 | AC20: GTPL_RJT_10202 | AD20: 14167730 | AJ20: Active
A21: 20 | B21: New | C21: 3763892 | E21: GTPL_RJT_10203 | F21: Vision Hi-Speed Technology Pvt. Ltd | G21: 45 | H21: Airtel | I21: P2P | J21: Rajkot | K21: Naranpura, Ahmedabad | L21: Gujarat | M21: SAQ/PVG/001 | N21: AMD/SHP/901 | Q21: 3763892 | R21: SAQ_BCLGJ_PVG_P_E82688_TS1-2 | S21: AMD_SHP_901_1AC_M_HAT950BR069>dis cu interface GigabitEthernet0/2/6 | T21: NA | U21: NA | V21: NA | W21: NA | X21: NA | Z21: 44285 | AB21: 44285 | AC21: GTPL_RJT_10203 | AD21: 13873952 | AJ21: Active
A22: 21 | B22: New | C22: 3767299 | E22: GTPL_RJT_10201 | F22: Vision Hi-Speed Technology Pvt. Ltd | G22: 120 | H22: Airtel | I22: P2P | J22: Rajkot | K22: Sarangpur | L22: Gujarat | M22: RKT/NSS/032 | N22: BTQ/SAL/005 | Q22: 3767299 | R22: RKT/NSS/032 RKT_BCLGJ_NSS_P_E51932 TS3-3 | S22: BTQ/SAL/005 BTQ_BCLGJ_SAL_P_E59415 TS1-4 | T22: NA | U22: NA | V22: NA | W22: NA | X22: NA | Z22: 44286 | AB22: 44286 | AC22: GTPL_RJT_10201 | AD22: 13877673 | AJ22: Active
A23: 22 | B23: New | C23: 3763747 | E23: GTPL_RJT_10102 | F23: Vision Hi-Speed Technology Pvt. Ltd | G23: 45 | H23: Airtel | I23: P2P | J23: Rajkot | K23: Kuchiyadad | L23: Gujarat | M23: RKT/NSS/032 | N23: RKT/KYD/124 | Q23: 3763747 | R23: RKT/NSS/032 RKT_BCLGJ_NSS_P_E51932 TS3-4 | S23: RKT/KYD/124 RKT_BCLGJ_KYD_P_E97366 TS1-3 | T23: NA | U23: NA | V23: NA | W23: NA | X23: NA | Z23: 44295 | AB23: 44321 | AC23: GTPL_RJT_10102 | AD23: 13874031 | AJ23: Active
A24: 23 | B24: New | C24: 3789969 | E24: GTPL_BKN_10101 | F24: JMD INTERNET AND SERVICES PRIVATE LIMITED | G24: 200 | H24: Airtel | I24: ILL | J24: NA | K24: Bikaner | L24: Rajasthan | M24: NA | N24: BKN/BCH/007 | Q24: 3789969 | R24: NA | S24: BKN/BCH/007 - Gig Optical BKN_BCLRJ_BCH_P_E54642 TS3-1 | T24: 122.187.32.78 | U24: 255.255.255.252 | V24: 122.187.32.77 | W24: 103.74.220.0/22 | X24: NA | Y24: NA | Z24: 44320 | AB24: 44320 | AC24: GTPL_BKN_10101 | AD24: 13897251 | AJ24: Active | AK24: 44915
A25: 24 | B25: New | C25: 3784086 | E25: GTPL_KRN_10101 | F25: SAT INTERNATIONAL PRIVATE LIMITED | G25: 1100 | H25: Airtel | I25: P2P | J25: Delhi | K25: Karnal | L25: New Delhi - Haryana | M25: NDL/DVG/901 | N25: KRL/ECM/901 | Q25: 3784086 | R25: NDL_VSN_901_1AG_A_ASR1XXXR080# port 1/1/17 | S25: KRL_ECM_901_N1201 Port : TS2_2 | T25: NA | U25: NA | V25: NA | W25: NA | X25: NA | Z25: 44323 | AB25: 44324 | AC25: GTPL_KRN_10101 | AD25: 13890946 | AJ25: Active
A26: 25 | B26: New | C26: 3801358 | E26: GTPL_PTN_10101 | F26: HOSTAXIS NETWORK PRIVATE LIMITED | G26: 1000 | H26: Airtel | I26: ILL | J26: NA | K26: Patna | L26: Bihar | M26: NA | N26: PTN/KPC/096 | Q26: 3801358 | R26: NA | S26: PTN_BCLBR_KPC_P_C75976 port 1 | T26: 122.187.156.38 | U26: 255.255.255.252 | V26: 122.187.156.37 | W26: 103.194.70.0/23,103.208.20.0/24,103.208.21.0/24 | X26: NA | Y26: NA | Z26: 44333 | AB26: 44333 | AC26: GTPL_PTN_10101 | AD26: 13905378 | AJ26: Active
A27: 26 | B27: New + Upgrade | C27: 3841663 | E27: GTPL_AJM_10101 | F27: Rajasthan Internet Hub Pvt. Ltd | G27: 310 | H27: Airtel | I27: ILL | J27: NA | K27: Ajmer | L27: Rajasthan | M27: NA | N27: AJM/SUN/010 | Q27: 3841663 | R27: NA | S27: AJM_BCLRJ_SUN_P_E90930 TS6-1 | T27: 122.186.79.10 | U27: 255.255.255.252 | V27: 122.186.79.9 | X27: NA | Y27: NA | Z27: 44337 | AB27: 44334 | AC27: GTPL_AJM_10101 | AD27: 13924371 | AF27: 155 | AG27: 310 | AH27: 155 | AI27: 44621 | AJ27: Active | AK27: 44846
A28: 27 | B28: New + Upgrade | C28: NA | E28: GTPL_DEL_34903 | F28: SAT INTERNATIONAL PRIVATE LIMITED | G28: 300 | H28: TCL | I28: ILL | J28: NA | K28: New Delhi | L28: New Delhi | M28: NA | N28: NA | Q28: NA | R28: NA | S28: DL-ME01-ICR02 ( XE-4/1/5:3 ) | T28: 14.143.159.254 | U28: 255.255.255.252 | V28: 14.143.159.253 | W28: 103.74.88.0/22, 103.74.88.0/24, 103.74.89.0/24, 103.74.90.0/24, 103.74.91.0/24 | X28: NA | Y28: NA | Z28: 44344 | AB28: 44344 | AC28: GTPL_DEL_34903 | AD28: 091DELH0300A0022803 | AJ28: Active
A29: 28 | B29: New + Upgrade | C29: 3797857 | E29: GTPL_PTN_10103 | F29: HOSTAXIS NETWORK PRIVATE LIMITED | G29: 1500 | H29: Airtel | I29: P2P | J29: Mumbai | K29: Patna | L29: Maharashtra - Bihar | M29: MUM/OIS/901 | N29: PTN/KPC/096 | Q29: 3797857 | R29: MUM_OIS_901_21AC_B_CNCS540R1145 Te0/0/0/19 | S29: PTN_BCLBR_KPC_P_C65531 Port: 3 | T29: NA | U29: NA | V29: NA | W29: NA | X29: NA | Z29: 44347 | AB29: 44286 | AC29: GTPL_PTN_10103 | AD29: 13903226 | AF29: 1000 | AG29: 1500 | AH29: 500 | AI29: 44666 | AJ29: Active
A30: 29 | B30: New + Upgrade | C30: 3841662 | E30: GTPL_AJM_10102 | F30: Rajasthan Internet Hub Pvt. Ltd | G30: 512 | H30: Airtel | I30: P2P | J30: Noida | K30: Ajmer | L30: Uttar Pradesh - Rajasthan | M30: NOD/STE/901 | N30: AJM/SUN/010 | Q30: 3841662 | R30: NOD/STE/901_NOD_STE_901_1AG_A_ASR1XXXR066#1/1/7_VLAN_2000 | S30: AJM/SUN/010 AJM_BCLRJ_SUN_P_E58958 TS1-3 | T30: NA | U30: NA | V30: NA | W30: NA | X30: NA | Y30: 2000 | Z30: 44347 | AB30: 44286 | AC30: GTPL_AJM_10102 | AD30: 13924120 | AF30: 310 | AG30: 512 | AH30: 202 | AI30: 44439 | AJ30: Active | AK30: 44868
A31: 30 | B31: New | C31: 3838132 | E31: GTPL_PTN_10102 | F31: HOSTAXIS NETWORK PRIVATE LIMITED | G31: 500 | H31: Airtel | I31: P2P | J31: Patna | K31: Muzzafarpur | L31: Bihar | M31: PTN/KPC/096 | N31: MUZ/BCL/036 | Q31: 3838132 | R31: PTN_BCLBR_KPC_P_C75976,Port 7 | S31: MUZ_BCLBR_BCL_P_C78100,Port 3 | T31: NA | U31: NA | V31: NA | W31: NA | X31: NA | Z31: 44350 | AB31: 44350 | AC31: GTPL_PTN_10102 | AD31: 13923191 | AJ31: Active
A32: 31 | B32: New + Upgrade + Downgrade | C32: 3853127 | E32: GTPL_RAN_10101 | F32: PROTOACT DIGITAL NETWORK PRIVATE LIMITED | G32: 1100 | H32: Airtel | I32: P2P | J32: Ranchi | K32: Jamshedpur | L32: Jharkhand | M32: RCH/UAT/057 | N32: JSP/SMK/013 | Q32: 3853127 | R32: RCH-BCLJH-UAT-T5-CN52_135 port 2 L2 poi vlan 1216 | S32: JSP_BCLJH_SMK_P_C64364,Port 16 | T32: NA | U32: NA | V32: NA | W32: NA | X32: NA | Y32: 1216 | Z32: 44350 | AB32: 44350 | AC32: GTPL_RAN_10101 | AD32: 13930730 | AF32: 2000 | AG32: 1100 | AH32: 900 | AI32: 44683 | AJ32: Active
A33: 32 | B33: New + Upgrade | C33: 3838121 | E33: GTPL_AJM_10103 | F33: Rajasthan Internet Hub Pvt. Ltd | G33: 155 | H33: Airtel | I33: P2P | J33: Ajmer | K33: Pushakar | L33: Rajasthan | M33: AJM/SUN/010 | N33: PUU/MBS/002 | Q33: 3838121 | R33: TS1-P2_AJM_BCLRJ_SUN_P_E58958 VLAN-104 | S33: PUU_BCLRJ_MBS_P_E80928-TS2-4 | T33: NA | U33: NA | V33: NA | W33: NA | X33: NA | Y33: 104 | Z33: 44355 | AB33: 44355 | AC33: GTPL_AJM_10103 | AD33: 13923450 | AF33: 45 | AG33: 155 | AH33: 110 | AI33: 44453 | AJ33: Inactive | AK33: 44522
A34: 33 | B34: New | C34: 3838120 | E34: GTPL_AJM_10104 | F34: Rajasthan Internet Hub Pvt. Ltd | G34: 100 | H34: Airtel | I34: P2P | J34: Ajmer | K34: Gagvana | L34: Rajasthan | M34: AJM/SUN/010 | N34: KGH/GGV/006 | Q34: 3838120 | R34: TS1-P2_AJM_BCLRJ_SUN_P_E58958 VLAN-103 | S34: KGH_BCLRJ_GGV_P_E80468_TS3-3 | T34: NA | U34: NA | V34: NA | W34: NA | X34: NA | Y34: 103 | Z34: 44357 | AB34: 44357 | AC34: GTPL_AJM_10104 | AD34: 13923451 | AF34: 200 | AG34: 100 | AH34: -100 | AI34: 44656 | AJ34: Active | AK34: 44868
A35: 34 | B35: New | C35: 3808920 | E35: GTPL_JODH_10101 | F35: NCORE CREATIVE TECHNOLOGIES PRIVATE LIMITED | G35: 45 | H35: Airtel | I35: P2P | J35: Jodhpur | K35: Balesar | L35: Rajasthan | M35: RAB/BAO/001 | N35: AOI/BAL/003 | Q35: 3808920 | R35: RAB_BCLRJ_BAO_P_E59617/TS1-1 | S35: AOI_BCLRJ_BAL_P_E81881/TS1-1 | T35: NA | U35: NA | V35: NA | W35: NA | X35: NA | Z35: 44361 | AB35: 44357 | AC35: GTPL_JODH_10101 | AD35: 13914439 | AJ35: Inactive | AK35: 44678
A36: 35 | B36: New | C36: 3838122 | E36: GTPL_AJM_10105 | F36: Rajasthan Internet Hub Pvt. Ltd | G36: 45 | H36: Airtel | I36: P2P | J36: Ajmer | K36: Kishangarh | L36: Rajasthan | M36: AJM/SUN/010 | N36: KGH/NTE/001 | Q36: 3838122 | R36: AJM/SUN/010_AJM_BCLRJ_SUN_P_E58958_TS1-P2 | S36: KGH_BCLRJ_NTE_P_E86782 XSA-P4 | T36: NA | U36: NA | V36: NA | W36: NA | X36: NA | Z36: 44362 | AB36: 44362 | AC36: GTPL_AJM_10105 | AD36: 13923449 | AJ36: Inactive | AK36: 44522
A37: 36 | B37: New | C37: NA | E37: GTPL_MUM_33919 | F37: PROTOACT DIGITAL NETWORK PRIVATE LIMITED | G37: 500 | H37: TCL | I37: ILL | J37: NA | K37: Mumbai | L37: Maharashtra | M37: NA | N37: NA | Q37: NA | R37: NA | S37: MMB_NIDC5_3FPOD2_HWI910_01//[HP]1GbE.1.12.1[GE-1-2-12 | T37: 121.242.107.190 | U37: 255.255.255.252 | V37: 121.242.107.189 | W37: 103.117.202.0/24,103.117.203.0/24,103.136.82.0/24, 103.136.83.0/24, 103.195.253.0/24, 103.144.114.0/24, 103.144.115.0/24, 103.146.222.0/24, 103.149.97.0/24 , 103.146.223.0/24, 103.16.104.0/22, 103.112.23.0/24, 103.112.21.0/24, 103.112.22.0/24 | X37: NA | Y37: NA | Z37: 44362 | AB37: 44362 | AC37: GTPL_MUM_33919 | AD37: 091MUMB0300A0022683 | AJ37: Inactive | AK37: 44729
A38: 37 | B38: New | C38: 3838124 | E38: GTPL_AJM_10106 | F38: Rajasthan Internet Hub Pvt. Ltd | G38: 45 | H38: Airtel | I38: P2P | J38: Ajmer | K38: Banswara | L38: Rajasthan | M38: AJM/SUN/010 | Q38: 3838124 | R38: AJM_BCLRJ_SUN_P_E58958_TS1-P2 | S38: BSW_BCLRJ_NZP_P_E61371 TS1-1 | T38: NA | U38: NA | V38: NA | W38: NA | X38: NA | Z38: 44363 | AB38: 44363 | AC38: GTPL_AJM_10106 | AD38: 13923447 | AJ38: Inactive | AK38: 44522
A39: 38 | B39: New + Upgrade | C39: 3861480 | E39: GTPL_RAN_10102 | F39: PROTOACT DIGITAL NETWORK PRIVATE LIMITED | G39: 500 | H39: Airtel | I39: P2P | J39: Ranchi | K39: Jahanabad | L39: Jharkhand - Bihar | M39: RCH/UAT/057 | N39: JAD/AWM/001 | Q39: 3861480 | R39: RCH-BCLJH-UAT-T5-CN52_135 port:2 | S39: JAD_BCLBR_AWM_P_C77532 | T39: NA | U39: NA | V39: NA | W39: NA | X39: NA | Y39: 1210 | Z39: 44365 | AB39: 44365 | AC39: GTPL_RAN_10102 | AD39: 13933626 | AF39: 500 | AG39: 700 | AH39: 200 | AI39: 44435 | AJ39: Active
A40: 39 | B40: New | C40: 3796664 | E40: GTPL_JPR_10207 | F40: NCORE CREATIVE TECHNOLOGIES PRIVATE LIMITED | G40: 45 | H40: Airtel | I40: P2P | J40: Noida | K40: Dhan Mandi | L40: Uttar Pradesh - Rajasthan | M40: NOD/STE/901 | N40: BND/NDM/003 | Q40: 3796664 | R40: NOD_STE_901_1AG_A_ASR1XXXR066#1/1/7_VLAN_1015 | S40: BND_BCLRJ_NDM_P_E55703 TS4-1 | T40: NA | U40: NA | V40: NA | W40: NA | X40: NA | Y40: 1015 | Z40: 44368 | AB40: 44368 | AC40: GTPL_JPR_10207 | AD40: 13901803 | AJ40: Active
...

Sheet Link Shifting
A1: Sr. No. | B1: Type of Order(New/Upgrade) | C1: Customer Name | D1: BW | E1: Provider | F1: Services | G1: Location From | H1: Location To | I1: Old END A BTS ID | J1: Old END B BTS ID | K1: END A BTS ID | L1: END B BTS ID | M1: Indent Number | N1: RA Received Date | O1: RA Number | Q1: Old End A Port | R1: Old End B Port | S1: END A Port | T1: END B Port | U1: IP Address | V1: Subnet | W1: Gateway | X1: LAN IP POOL | Y1: IPV6 LAN IP Pool | Z1: VLAN | AA1: GTPL Circuit ID | AB1: DC Airtel CKT ID | AC1: AIRTEL Circuit ID | AD1: Status
A2: 1 | B2: Link shifting | C2: Royal Connect Solutions Pvt Ltd | D2: 1000 | E2: Airtel | F2: ILL | G2: NA | H2: Jaipur | I2: NA | J2: JPR/JMA/902 | K2: NA | L2: JPR/RSW/901 | M2: 1052002100 | N2: 44565 | O2: 4069722 | Q2: NA | R2: JPR_JMA_902_1AC Port : 1/4/6 | S2: NA | T2: JPR_RSW_901_1AC_M_ASAR8XXR009#1/6/5 | U2: 122.186.83.130 | V2: 255.255.255.252 | W2: 122.186.83.129 | X2: 103.118.168.0/22 | Y2: NA | Z2: NA | AA2: GTPL_JPR_10201 | AB2: NA | AC2: 13874456
A3: 2 | B3: Link shifting | C3: NCORE CREATIVE TECHNOLOGIES PRIVATE LIMITED | D3: 45 | E3: Airtel | F3: P2P | G3: Jodhpur | H3: Mandore, Jodhpur | I3: NOD/STE/901 | J3: JOD/NGK/032 | K3: JMD/MMR/009 | L3: JOD/NGK/032 | O3: 4042420 | Q3: NOD_STE_901_1AG_A_ASR1XXXR066#100.64.2.22 1/1/7 VLAN 2002 | R3: JOD_BCLRJ_NGK_P_E54886 TS1-1 | S3: JOD_BCLRJ_MMR_P_E54881 TS1- 3 | T3: JOD_BCLRJ_NGK_P_E54886 TS1-1 | U3: NA | V3: NA | W3: NA | X3: NA | Y3: NA | Z3: 1100 | AA3: GTPL_JODH_10102 | AB3: 13901805 | AC3: 14107305
A4: 3 | B4: Link shifting | C4: BIG DATA BROADBAND PVT LTD | D4: 150 | E4: Airtel | F4: P2P | G4: Mumbai | H4: Burun | I4: MUM/1SR/901 | J4: DDG/MAK/001 | K4: MUM/1SR/901 | L4: AGB/PMR/017 | O4: 4042425 | Q4: MUM_OIS_901_22AC_B_CNCS540R1171#Te0/0/0/15.2001 | R4: DDG_BCLBR_MAK_P_C62771-Port 24 | S4: MUM_OIS_901_22AC_B_CNCS540R1171#Te0/0/0/15.2001 | T4: AGB_BCLBR_PMR_P_C79311 Port 4 | U4: NA | V4: NA | W4: NA | X4: NA | Y4: NA | Z4: 2001 | AA4: GTPL_MUM_33936 | AB4: 13959769 | AC4: 14108079
A5: 4 | B5: Link shifting | C5: ADARSH INFOSOLUTIONS (P) LIMITED | D5: 45 | E5: Airtel | F5: P2P | G5: Mumbai | H5: Tembode | I5: MUM/XWY/901 | J5: RAR/PAA/003 | K5: MUM/XWY/901 | L5: PGR/TEM/011 | O5: 4042426 | Q5: MUM_XWY_901_5AC_B_HAT950BR513 GigabitEthernet0/3/0 VLAN : 4052 | R5: RAR_BCLMH_PAA_P_E51089-TS7-2 | S5: MUM_XWY_901_5AC_B_HAT950BR513 --> GigabitEthernet0/3/0 | T5: PGR_BCLMH_TEM_P_E82635 TS3-2 | U5: NA | V5: NA | W5: NA | X5: NA | Y5: NA | Z5: 4052 | AA5: GTPL_ENT_10045 | AB5: 13996541 | AC5: 14108078
A6: 5 | B6: Link shifting | C6: ADARSH INFOSOLUTIONS (P) LIMITED | D6: 500 | E6: Airtel | F6: P2P | G6: Mumbai | H6: Osmanabad | I6: MUM/XWY/901 | J6: OSD/OAC/013 | K6: MUM/XWY/901 | L6: TAB/SMN/002 | M6: 1073000700 | O6: 4071309 | Q6: MUM_XWY_901_5AC_B_HAT950BR513- GigabitEthernet0/3/0 VLAN: 4008 | R6: OSD_BCLMH_OAC_P_E58182 TS3-2 | S6: MUM_XWY_901_5AC_B_HAT950BR513- GigabitEthernet0/3/0 VLAN: 4008 | T6: TAB_BCLMH_SMN_P_E99358 TS3-4 | U6: NA | V6: NA | W6: NA | X6: NA | Y6: NA | Z6: 4008 | AA6: GTPL_MUM_33926 | AB6: 13937678 | AC6: 14133417
A7: 6 | B7: Link shifting | C7: NCORE CREATIVE TECHNOLOGIES PRIVATE LIMITED | D7: 45 | E7: Airtel | F7: P2P | G7: Jodhpur | H7: Balesar | I7: RAB/BAO/001 | J7: AOI/BAL/003 | K7: RAB/BAO/001 | L7: BAF/MNV/001 | N7: 44561 | O7: 4067031 | Q7: RAB_BCLRJ_BAO_P_E59617/TS1-1 | R7: AOI_BCLRJ_BAL_P_E81881/TS1-1 | S7: RAB_BCLRJ_BAO_P_E59617/TS1-1 | T7: BAF_BCLRJ_MNV_P_E54069 Port : TS3-2 | U7: NA | V7: NA | W7: NA | X7: NA | Y7: NA | Z7: NA | AA7: GTPL_JODH_10101 | AB7: 13914439 | AC7: 14129363 | AD7: link shifting cancel by customer
A8: 7 | B8: Link shifting | C8: ADARSH INFOSOLUTIONS (P) LIMITED | D8: 155 | E8: Airtel | F8: P2P | G8: Mumbai | H8: Phulambary | I8: MUM/XWY/901 | J8: SGO/KLW/021 | K8: MUM/XWY/901 | L8: PMB/CHP/001 | M8: 1072010100 | O8: 4088265 | S8: MUM_XWY_901_5AC Port : 0/3/0 VLAN: 4003 | U8: NA | V8: NA | W8: NA | X8: NA | Y8: NA | Z8: 4003 | AA8: GTPL_MUM_33929 | AB8: 13943967 | AC8: 14145064 | AD8: link shifting cancel by customer
A9: 8 | B9: Link shifting | C9: MEGATEL NETWORKS PVT LTD | D9: 1000 | E9: Airtel | F9: P2P | G9: Siliguri | H9: Mainaguri | I9: CHN/SAN/930 | J9: KAR/VNR/005 | K9: SIL/VDP/050 | L9: MRF/PSM/001 | M9: 3152000900 | N9: 44603 | O9: 4105050 | Q9: CHN_SAN_901_3AC_T_CNCS540R933#show run int TenGigE0/0/0/20|Vlan-1933 | R9: KAR_BCLTN_VNR_P_E54193 TS7-2 | S9: SIL-BCLWB-VDP-T5-CN24-166 Port-5 | T9: MRF_BCLBR_PSM_P_C66189 Port -8 | U9: NA | V9: NA | W9: NA | X9: NA | Y9: NA | Z9: NA | AA9: GTPL_KAR_10291 | AB9: 14110222 | AC9: 14155450
A10: 9 | B10: Link shifting | C10: BIG DATA BROADBAND PVT LTD | D10: 155 | E10: Airtel | F10: P2P | G10: Mumbai | H10: Dehri | I10: MUM/OIS/901 | J10: GYA/CLG/001 | K10: MUM/OIS/901 | L10: DEH/RPM/001 | M10: 1073002900 & 1063001400 | O10: 4196493 | Q10: MUM_OIS_901_22AC_B_CNCS540R1171 - Te0/0/0/15.2013 | R10: GYA_TNGBR_CLG_P_C70157 port 5/2 | S10: MUM_OIS_901_22AC_B_CNCS540R1171 - Te0/0/0/15.2013 | T10: DEH_BCLBR_RPM_P_C66244 Port 1 | U10: NA | V10: NA | W10: NA | X10: NA | Y10: NA | AA10: GTPL_ENT_10012 | AB10: 13996169 | AC10: 14220160
A11: 10 | B11: Link shifting | C11: Vision Hi-Speed Technology Pvt. Ltd | D11: 45 | E11: Airtel | F11: P2P | G11: Rajkot | H11: Sarangpur | I11: RKT/NSS/032 | J11: BTQ/SAL/005 | K11: RKT/ADP/089 | L11: BTQ/SAL/005 | M11: 1002153100 | N11: 44620 | O11: 4123267 | Q11: END A: RKT/NSS/032 RKT_BCLGJ_NSS_P_E51932 TS4-2 | R11: END B: BTQ/SAL/005 BTQ_BCLGJ_SAL_P_E59415 TS1-3 | S11: RKT_BCLGJ_ADP_P_E82931/TS1-3 | T11: BTQ/SAL/005 BTQ_BCLGJ_SAL_P_E59415 TS1-3 | U11: NA | V11: NA | W11: NA | X11: NA | Y11: NA | Z11: NA | AA11: GTPL_RJT_10202 | AB11: 13873951 | AC11: 14167730
A12: 11 | B12: Link shifting | C12: PROTOACT DIGITAL NETWORK PRIVATE LIMITED | D12: 500 | E12: Airtel | F12: P2P | G12: Ranchi | H12: Jamshedpur | I12: RCH/UAT/057 | J12: RNA/KMH/001 | K12: RCH/UAT/057 | L12: JSP/VKH/053 | M12: 1093000700 | N12: 44676 | O12: 4173741 | Q12: RCH-BCLJH-UAT-T5-CN52_135 port 2 L2 poi 1214 | R12: RNA_BCLBR_KMH_P_C62124 Port 11 | S12: RCH-BCLJH-UAT-T5-CN52_135 port 2 L2 poi 1229 | T12: JSP-BCLJH-VKH-T5-CN52_233 (100.73.52.233) Port 2 | U12: NA | V12: NA | W12: NA | X12: NA | Y12: NA | Z12: 1214 | AA12: GTPL_ENT_10006 | AB12: 13983092 | AD12: link shifting cancel by customer
A13: 12 | B13: Link shifting | C13: ADARSH INFOSOLUTIONS (P) LIMITED | D13: 512 | E13: Airtel | F13: P2P | G13: Shirpur | H13: Khetiya | I13: MUM/XWY/901 | J13: KHA/GTH/002 | K13: SPH/KGN/005 | L13: KHA/GTH/002 | M13: 1073001900 & 3293000100 | N13: 44671 | O13: 4168557 | Q13: MUM_XWY_901_5AC_B_HAT950BR513-GigabitEthernet0/3/0.4046 | R13: KHA-BCLMP-GTH-T5-ER64.126 VLAN:4046 | S13: SPH_BCLMH_KGN_P_E85687 TS1-1 | T13: KHA-BCLMP-GTH-T5-ER64.126 GIG OPTICAL TS1-3 | U13: NA | V13: NA | W13: NA | X13: NA | Y13: NA | AA13: GTPL_MUM_33931 | AB13: 13959551 | AC13: 14202722
A14: 13 | B14: Link shifting | C14: MEGATEL NETWORKS PVT LTD | D14: 500 | E14: Airtel | F14: P2P | G14: Mangalagiri | H14: Mella Chervu | I14: HTS/RMI/005 | J14: AGG/AWC/001 | K14: MGL/BRS/004 | L14: NGD/APM/024 | M14: 1042022300 & 1282006100 | N14: 44659 | O14: 4154924 | Q14: HTS_BCLUP_RMI_P_C81825 Port 3 Vlan 2011 | R14: AGG_BCLUP_AWC_P_C66817 Port 6 | S14: MGL_FTTAP_BRS_P_E82241 XSA-1 | T14: NGD_BCLAP_APM_P_E88800 TS3-3 | U14: NA | V14: NA | W14: NA | X14: NA | Y14: NA | AA14: GTPL_HTFH_10332 | AB14: 14110305 | AC14: 14189686
A15: 14 | B15: Link shifting | C15: ADARSH INFOSOLUTIONS (P) LIMITED | D15: 100 | E15: Airtel | F15: P2P | G15: Mumbai | H15: Sillod | I15: MUM/XWY/901 | J15: SAN/JKI/013 | K15: MUM/XWY/901 | L15: SLD/BCL/001 | M15: 1073002700 | N15: 44681 | O15: 4178230 | Q15: MUM_XWY_901_11AC_B_HAT910CR838 GigabitEthernet 0/2/2 VLAN: 3091 | R15: SAN_BCLMH_KJI_P_E53886_TS4-3 (OTGBE SFP req) | S15: MUM_XWY_901_11AC_B_HAT910CR838>disp current-configuration int GigabitEthernet0/2/2.3085 | T15: SLD_BCLMH_BCL_P_E50495 TS3-3 | U15: NA | V15: NA | W15: NA | X15: NA | Y15: NA | Z15: 3091 | AA15: GTPL_MUM_10529 | AB15: 14076447 | AC15: 14211502
A16: 15 | B16: Link shifting | C16: MEGATEL NETWORKS PVT LTD | D16: 1000 | E16: Airtel | F16: P2P | G16: Mumbai | H16: Nasipur | I16: MUM/OIS/901 | J16: BHB/VMJ/001 | K16: MUM/OIS/901 | L16: BHB/BBO/014 | M16: 1073002300 & 3153000300 | N16: 44672 | O16: 4168560 | Q16: MUM_OIS_901_27AC_B_CNCS540R1226 100.64.77.194 Port : TenGigE0/0/0/21 VLAN: 504 | R16: BHB_BCLWB_VMJ_P_C74093 Port 15 | S16: MUM_OIS_901_27AC_B_CNCS540R1226 100.64.77.194 Port : TenGigE0/0/0/21 VLAN: 504 | T16: BHB_BCLWB_BBO_P_C80219 Port 3 | U16: NA | V16: NA | W16: NA | X16: NA | Y16: NA | Z16: 504 | AA16: GTPL_MUMBHB_10322 | AB16: 14113609 | AD16: link shifting cancel by customer
A17: 16 | B17: Link shifting | C17: Net4U Technology | D17: 150 | E17: Airtel | F17: P2P | G17: Udaipur | H17: Salumer | I17: UPR/MVS/018 | J17: UPR/AMT/003 | K17: UPR/MVS/018 | L17: SLU/BWR/001 | M17: 1323000700 | N17: 44672 | O17: 4168558 | Q17: UPR_BCLRJ_MVS_P_E53120/TS4-2 VLAN - 2002 | R17: UPR/AMT/003 GIG OPTICAL UPR_BCLRJ_AMT_P_E53398 TS7-2 (REQ-OTGBE) | S17: UPR_BCLRJ_MVS_P_E53120/TS4-2 VLAN - 2002 | T17: SLU_BCLRJ_BWR_P_ E63296 TS1-1 | U17: NA | V17: NA | W17: NA | X17: NA | Y17: NA | Z17: 2002 | AA17: GTPL_UDP_10231 | AB17: 14084292 | AC17: 14203155
A18: 17 | B18: Link shifting | C18: PROTOACT DIGITAL NETWORK PRIVATE LIMITED | D18: 800 | E18: Airtel | F18: P2P | G18: Ranchi | H18: Bihar Sharif | I18: RCH/NPD/081 | J18: BSF/BCC/003 | K18: RCH/UAT/057 | L18: BSF/BCC/003 | M18: 1093000800 & 1063001300 | N18: 44720 | O18: 4211263 | Q18: RCH_BCLJH_NPD_P_C64439 port 11 VLAN : 1700 | R18: BSF_BCLBR_BCC_P_C73600 Port 13 | S18: RCH-BCLJH-UAT-T5-CN52_135 (100.73.52.135) Port 2 Vlan 1239 | T18: BSF_BCLBR_BCC_P_C73600 Port 13 | U18: NA | V18: NA | W18: NA | X18: NA | Y18: NA | AA18: GTPL_RCHBCF_10401 | AB18: 14133613 | AC18: 14133613 | AD18: Active
A19: 18 | B19: Link shifting | C19: Vihaan Telecom | D19: 50 | E19: Airtel | F19: P2P | G19: Ahmedabad | H19: Gavasad | I19: BRD/BSC/028 | J19: GVS/NSA/001 | K19: AMD/VHT/901 | L19: GVS/NSA/001 | M19: 1003027000 | N19: 44720 | O19: 4212815 | Q19: BRD_BCLGJ_BSC_P_E97760 TS3-2 | R19: GVS_BCLGJ_NSA_P_E51990 TS4-1 | S19: AMD_VHT_901_1AC_B_HAT950BR048>disp current-configuration int gig 0/1/7 VLAN - 1012 | T19: GVS_BCLGJ_NSA_P_E51990 TS4-1 | U19: NA | V19: NA | W19: NA | X19: NA | Y19: NA | AA19: GTPL_BRD_10219 | AB19: 14106624 | AD19: Testing WIP
A20: 19 | B20: Link shifting | C20: ADARSH INFOSOLUTIONS (P) LIMITED | D20: 155 | E20: Airtel | F20: P2P | G20: Mumbai | H20: Bhiwandi | I20: MUM/XWY/901 | J20: HAO/VSI/001 | K20: MUM/XWY/901 | L20: BHW/BBY/008 | M20: 1073003800 | N20: 44695 | O20: 4192302 | Q20: MUM_XWY_901_5AC_B_HAT950BR513-GigabitEthernet0/3/0 VLAN: 4004 | R20: HAO_BCLMH_VSI_P_E51178 TS6-4 | S20: MUM_XWY_901_5AC_B_HAT950BR513-GigabitEthernet0/3/0 VLAN : 4092 | T20: BHW_BCLMH_BBY_P_E51583 TS7-2 | U20: NA | V20: NA | W20: NA | X20: NA | Y20: NA | AA20: GTPL_MUM_33924 | AB20: 13943995 | AC20: 14217073
A21: 20 | B21: Link shifting | C21: ZYE TELECOM PRIVATE LIMITED | D21: 155 | E21: Airtel | F21: P2P | G21: Hyderabad | H21: Muluingu | I21: HYD/CTS/902 | J21: INC/MUL/022 | K21: HYD/CTS/902 | L21: KIX/TLY/001 | Q21: HYD_CTS_903_C6501_T Port SH1-SL11-P18, SH1-SL13-P18 VLAN : 3631 | R21: INC/MUL/002 GIG OPTICAL INC_BCLAP_MUL_P_E97310 TS3-2 | S21: HYD_CTS_903_C6501_T Port SH1-SL11-P18, SH1-SL13-P18 VLAN : 3622 | T21: KIX_BCLAP_TLY_P_E62242 TS1-1 | U21: NA | V21: NA | W21: NA | X21: NA | Y21: NA | AA21: GTPL_HYD_10310 | AB21: 14043560 | AC21: 14141113
A22: 21 | B22: Link shifting | C22: ARICHWAL IT SERVICES PVT LTD | D22: 500 | E22: Airtel | F22: P2P | G22: New Delhi | H22: Taranagar | I22: NDL/TTB/901 | J22: STG/PRN/011 | K22: NDL/TTB/901 | L22: TNG/SRD/001 | M22: 3093000500 & 1323001700 | N22: 44697 | O22: 4192306 | Q22: NDL_TTB_901_8AC Port : 1/1/7 VLAN : 1500 | R22: SGN_BCLRJ_MKG_P_E87120 TS6-4 | S22: NDL_TTB_901_8AC Port : 1/1/7 VLAN : 1500 | T22: TNG_BCLRJ_SRD_P_E50415 TS4-3 | U22: NA | V22: NA | W22: NA | X22: NA | Y22: NA | AA22: GTPL_RAJ_10226 | AB22: 13959930 | AC22: 14217401
A23: 22 | B23: Link shifting | C23: Vision Hi-Speed Technology Pvt. Ltd | D23: 45 | E23: Airtel | F23: P2P | G23: Halvad | H23: Kuchiyadad | I23: RKT/NSS/032 | J23: RKT/KYD/124 | K23: HVL/BPN/003 | L23: RKT/KYD/124 | M23: 1003052100 | N23: 44740 | O23: 4226517 | Q23: RKT/NSS/032 RKT_BCLGJ_NSS_P_E51932 TS3-4 | R23: RKT/KYD/124 RKT_BCLGJ_KYD_P_E97366 TS1-3 | T23: RKT/KYD/124 RKT_BCLGJ_KYD_P_E97366 TS1-3 | U23: NA | V23: NA | W23: NA | X23: NA | Y23: NA | AA23: GTPL_RJT_10102 | AB23: 13874031 | AD23: provisioning wip
A24: 23 | B24: Link shifting | C24: ZYE TELECOM PRIVATE LIMITED | D24: 200 | E24: Airtel | F24: P2P | G24: Hyderabad | H24: Yanam | I24: HYD/CTS/902 | J24: TWA/MDP/002 | K24: HYD/CTS/902 | L24: YAN/KAM/001 | O24: 4198041 | Q24: HYD_CTS_903_C6501_T Port SH1-SL11-P18, SH1-SL13-P18 VLAN 3611 | R24: TWA/MDP/002 TWA_BCLAP_MDP_P_E99507 TS1-1 | S24: HYD_CTS_903_C6501_T Port SH1-SL11-P18, SH1-SL13-P18 VLAN : 2459 | T24: YAN_BCLAP_KAM_P_E61703 XSB-4 | U24: NA | V24: NA | W24: NA | X24: NA | Y24: NA | AA24: GTPL_ENT_10098 | AB24: 13986765 | AC24: 14221888
A25: 24 | B25: Link shifting | C25: MEGATEL NETWORKS PVT LTD | D25: 155 | E25: Airtel | F25: ILL | G25: NA | H25: Hatharas | I25: NA | J25: HTS/RMI/005 | K25: NA | L25: NDL/ATC/901 | M25: 3093001200 | N25: NA | O25: NA | Q25: NA | R25: HTS_BCLUP_RMI_P_C81825 port 2 | S25: NA | T25: NA | U25: 182.66.121.74 | V25: 255.255.255.252 | W25: 182.66.121.73 | X25: 103.139.66.0/24 & 103.139.67.0/24 & 103.160.196.0/24 & 103.160.197.0/24 | Y25: NA | Z25: NA | AA25: GTPL_HTR_10494 | AB25: 14111816 | AD25: NA
A26: 25 | B26: Link shifting | C26: MEGATEL NETWORKS PVT LTD | D26: 2000 | E26: Airtel | F26: P2P | G26: Mumbai | H26: Haldia | I26: MUM/OIS/901 | J26: HLD/DCK/001 | K26: MUM/XVS/901 | L26: HLD/DCK/001 | M26: 1073005401 & 3153000800 | N26: 44739 | O26: 4223670 | Q26: MUM_OIS_901_27AC_B_CNCS540R1226#TenGigE0/0/0/21.502 | R26: HLD_BCLWB_DCK_P_C76834 Port 12 | S26: MUM_XVS_901_25AC_B_CNCS540R1326#sh l2v xc int TenGigE0/0/0/15.1044 | T26: HLD_BCLWB_DCK_P_C76834 Port 12 (Existing Port) | U26: NA | V26: NA | W26: NA | X26: NA | Y26: NA | AA26: GTPL_MUMHLD_10397 | AB26: 14113450 | AC26: 14248976 | AD26: Inactive
A27: 26 | B27: Link shifting | C27: MEGATEL NETWORKS PVT LTD | D27: 1000 | E27: Airtel | F27: P2P | G27: Mumbai | H27: Bhagwangola | I27: MUM/OIS/901 | J27: BHB/VMJ/001 | K27: MUM/XVS/901 | L27: BHB/VMJ/001 | M27: 1073005402 & 3153000801 | N27: 44753 | O27: 4237096 | Q27: MUM_OIS_901_27AC_B_CNCS540R1226 100.64.77.194 Port : TenGigE0/0/0/21 VLAN: 504 | R27: BHB_BCLWB_VMJ_P_C74093 Port 15 | S27: MUM_XVS_901_20AC_B_CNCS540R1134# TenGigE0/0/0/27.1001 | T27: BHB_BCLWB_VMJ_P_C74093 Port 17 | U27: NA | V27: NA | W27: NA | X27: NA | Y27: NA | AA27: GTPL_MUMBHB_10322 | AB27: 14113609 | AC27: 14257883
A28: 27 | B28: Link shifting | C28: MEGATEL NETWORKS PVT LTD | D28: 500 | E28: Airtel | F28: P2P | G28: Mumbai | H28: Karimpur | I28: MUM/OIS/901 | J28: KMP/KBS/001 | K28: MUM/XVS/901 | L28: KMP/KBS/001 | M28: 1073005403 & 3153000802 | N28: 44739 | O28: 4223769 | Q28: MUM_OIS_901_27AC_B_CNCS540R1226 100.64.77.194 Port : TenGigE0/0/0/21 VLAN: 501 | R28: KMP_BCLWB_KBS_P_C75473 Port 3 | S28: MUM_XVS_901_20AC_B_CNCS540R1134 0/0/0/27 | T28: KMP_BCLWB_KBS_P_C75473 Port 3 | U28: NA | V28: NA | W28: NA | X28: NA | Y28: NA | AA28: GTPL_MUMKMP_10321 | AB28: 14113654 | AC28: 14248999
A29: 28 | B29: Link shifting | C29: MEGATEL NETWORKS PVT LTD | D29: 512 | E29: Airtel | F29: P2P | G29: Siliguri | H29: Sonipat | I29: MUM/OIS/901 | J29: MHB/MKP/002 | K29: SIL/VDP/050 | L29: SNP/NTC/012 | M29: 3153000900 & 4123001300 | N29: 44739 | O29: 4223740 | Q29: MUM_OIS_901_27AC_B_CNCS540R1226 100.64.77.194 Port : TenGigE0/0/0/23 VLAN: 301 | R29: MHB_BCLUP_HMT_P_C77164 Port 4 | S29: SNP_BCLHR_NTC_P_E51495 TS7-1 | T29: SIL-BCLWB-VDP-T5-CN26-177 Port 12 | U29: NA | V29: NA | W29: NA | X29: NA | Y29: NA | AA29: GTPL_MUMMAH_10497 | AB29: 14114612 | AC29: 14249019
A30: 29 | B30: Link shifting | C30: Chat Signal PVT LTD | D30: 45 | E30: Airtel | F30: P2P | G30: Mumbai | H30: Delgaun Mahi | I30: MUM/XWY/901 | J30: PGR/TEM/011 | K30: MUM/XWY/901 | L30: DEU/DRJ/002 | M30: 1073005400 | N30: 44739 | O30: 4223632 | Q30: MUM_XWY_901_5AC_B_HAT950BR513 --> GigabitEthernet0/3/0 | R30: PGR_BCLMH_TEM_P_E82635 TS3-2 | S30: MUM_XWY_901_5AC_B_HAT950BR513 --> GigabitEthernet0/3/0 | T30: DEU_BCLMH_DRJ_P_E59844 TS7-4 | U30: NA | V30: NA | W30: NA | X30: NA | Y30: NA | AA30: GTPL_MUM_10539 | AB30: 14108078 | AC30: 14248943
A31: 30 | B31: Link shifting | C31: DISHAWAVES INFONET PRIVATE LIMITED | D31: 500 | E31: Airtel | F31: P2P | G31: Ahmedabad | H31: Dharmaj | I31: AMD/MTR/901 | J31: SLV/VAI/012 | K31: AMD/MTR/901 | L31: ANA/NBS/008 | N31: 44756 | O31: 4238460 | Q31: AMD_MTR_901_3AC_B_HAT910CR157 100.64.10.138 interface GigabitEthernet0/2/3.1329 | R31: SLV_BCLGJ_VAI_P_E57296 TS1-4 | S31: AMD_MTR_901_2AC_B_HAT910CR110-GigabitEthernet0/2/3 VLAN -2658 | T31: ANA_BCLGJ_NBS_P_E53503 TS2-2 | U31: NA | V31: NA | W31: NA | X31: NA | Y31: NA | AA31: GTPL_AMDSLV_10393 | AB31: 14155535 | AC31: 14259425
A32: 31 | B32: Link shifting | C32: ZYE TELECOM PRIVATE LIMITED | D32: 310 | E32: Airtel | F32: P2P | G32: Hyderabad | H32: NANDALUR | I32: HYD/CTS/902 | J32: PLK/NDT/001 | K32: HYD/CTS/902 | L32: NLU/AVP/001 | O32: 4190029 | Q32: HYD_CTS_903_C6501_T' SH1-SL11-P18,SH1-SL13-P18 VLAN : 3619 | R32: PLK_BCLAP_NDT_P_E50623 TS1-1 | S32: HYD_CTS_903_C6501_T' SH1-SL11-P18,SH1-SL13-P18 VLAN : 695 | T32: NLU_BCLAP_AVP_P_E58489 TS2-2 | U32: NA | V32: NA | W32: NA | X32: NA | Y32: NA | AA32: GTPL_ENT_10010 | AB32: 13986764 | AC32: 14215749
A33: 32 | B33: Link shifting | C33: ZYE TELECOM PRIVATE LIMITED | D33: 500 | E33: Airtel | F33: P2P | G33: Hyderabad | H33: Laxmipuram | I33: HYD/CTS/902 | J33: JER/NTE/001 | K33: HYD/CTS/902 | L33: BXL/MPL/006 | O33: 4190866 | Q33: HYD_CTS_903_C6501_T' --> Port : SH1-SL11-P18,SH1-SL13-P18 --> VLAN : 3594 | R33: JER_BCLAP_NTE_P_E95558 GIG OPTICAL --> XSA-3 | S33: HYD_CTS_903_C6501_T' --> Port : SH1-SL11-P18,SH1-SL13-P18 --> VLAN : 4020 | T33: BXL_BCLAP_MPL_P_E93204 TS2-4 | U33: NA | V33: NA | W33: NA | X33: NA | Y33: NA | AA33: GTPL_ENT_10034 | AB33: 13956560 | AC33: 14217075
A34: 33 | B34: Link shifting | C34: HOSTAXIS NETWORK PRIVATE LIMITED | D34: 80 | E34: Airtel | F34: P2P | G34: Patna | H34: Motihari | I34: PTN/KPC/096 | J34: SHC/DSH/001 | K34: PTN/KPC/096 | L34: MHR/BHK/011 | M34: 1063002900 | Q34: PTN_BCLBR_KPC_P_C75976 PORT 9 Vlan 1012 | R34: SHC_BCLBR_DSH_P_C69381 PORT 22 | S34: PTN_BCLBR_KPC_P_C75976 PORT 9 Vlan 1012 | U34: NA | V34: NA | W34: NA | X34: NA | Y34: NA | AA34: GTPL_PTN_10294 | AB34: 14106325 | AD34: DoT Ack WIP
A35: 34 | B35: Link shifting | C35: ARICHWAL IT SERVICES PVT LTD | D35: 1100 | E35: Airtel | F35: P2P | G35: New Delhi | H35: Jhunjanu | I35: NDL/TTB/901 | J35: JJU/GYM/008 | K35: NDL/TTB/901 | L35: RWT/SNC/001 | M35: 3093001900 & 1323002600 | N35: 44761 | O35: 4242218 | Q35: NDL_TTB_901_8AC_B_IXREXXR873# 1/1/7:1503 | R35: RWT_BCLRJ_SNC_P_E96866 XSA-4 | S35: NDL_TTB_901_8AC_B_IXREXXR873# 1/1/7:1503 | T35: JJU_BCLRJ_GYM_P_E54161 TS2-2 | U35: NA | V35: NA | W35: NA | X35: NA | Y35: NA | AA35: GTPL_RWT_10472 | AB35: 14163939 | AC35: 14261647
A36: 35 | B36: Link shifting | C36: ZYE TELECOM PRIVATE LIMITED | D36: 310 | E36: Airtel | F36: P2P | G36: Hyderabad | H36: Kamanpuramandal | I36: HYD/CTS/902 | J36: NAS/ADD/001 | K36: HYD/CTS/902 | L36: KAA/IPR/042 | M36: 1043004400 | N36: 44773 | O36: 4255994 | U36: NA | V36: NA | W36: NA | X36: NA | Y36: NA | AA36: GTPL_NAS_10503 | AB36: 14146020 | AD36: link shifting cancel by customer
A37: 36 | B37: Link shifting | C37: ZYE TELECOM PRIVATE LIMITED | D37: 800 | E37: Airtel | F37: P2P | G37: Hyderabad | H37: Wanarpatthy | I37: HYD/CTS/902 | J37: KNPR/BRTE/001 | K37: HYD/CTS/902 | L37: WPY/PHS/001 | M37: 1043004100 | N37: 44759 | O37: 4247080 | Q37: HYD_CTS_903_C6501_T SH1-SL13-P1 VLAN: 3581 | R37: KNPR_BCLAP_BRTE_P_E94106 TS3-4 | S37: HYD_CTS_903_C6501_T Port SH1-SL11-P29 & SH1-SL13-P29 VLAN : 2534 | T37: WPY_BCLAP_PHS_P_E61303 Port : TS3-2 | U37: NA | V37: NA | W37: NA | X37: NA | Y37: NA | AA37: GTPL_ZYE_10323 | AB37: 13956612 | AC37: 14262195 | AD37: Active
A38: 37 | B38: Link shifting | C38: MEGATEL NETWORKS PVT LTD | D38: 512 | E38: Airtel | F38: P2P | G38: Mumbai | H38: Jagdalpur | I38: MUM/OIS/901 | J38: KSH/BAT/009 | K38: NOD/STE/901 | L38: KSH/BAT/009 | M38: 1073008300 & 3213000200 | N38: 44807 | O38: 4289305 | Q38: MUM_OIS_901_27AC_B_CNCS540R1226 Port : Te0/0/0/23 VLAN : 305 | R38: KSH_BCLHR_BAT_P_E55036 TS4-2 | S38: NOD_STE_901_1AG_A_ASR1XX, 1/1/18 | T38: KSH/BAT/009 KSH-BCLHR-BAT-T5-ER8.82 TS1-1 | U38: NA | V38: NA | W38: NA | X38: NA | Y38: NA | Z38: 2032 | AA38: GTPL_MUMKUR_10496 | AB38: 14114361 | AC38: 17486883 | AD38: Active
A39: 38 | B39: Link shifting | C39: SKYONLINE TECHNOSYSTEM PRIVATE LIMITED | D39: 45 | E39: Airtel | F39: P2P | G39: Jamnagar | H39: Khambhaliya | I39: JMN/KNT/001 | J39: KBL/OPP/001 | K39: JMN/NDA/004 | L39: KBL/OPP/001 | O39: 4278294 | Q39: JMN_BCLGJ_KNT_P_E52825 TS4-4 | R39: KBL_BCLGJ_OPP_P_E52164 TS6-4 | S39: JMN_BCLGJ_NDA_P_E82690 TS4_2 OTGBE REQ | T39: KBL_BCLGJ_OPP_P_E52164 TS6-4 | U39: NA | V39: NA | W39: NA | X39: NA | Y39: NA | AA39: GTPL_JAM_10208 | AB39: 14093763 | AD39: Active
A40: 39 | B40: Link shifting | C40: PROTOACT DIGITAL NETWORK PRIVATE LIMITED | D40: 200 | E40: Airtel | F40: P2P | G40: Godda | H40: Amarpara | I40: GOD/PSG/001 | J40: BZC/VBI/001 | K40: GOD/PSG/001 | L40: AMH/DPR/002 | M40: 1093002203 | O40: 4301027 | Q40: GOD_BCLBR_PSG_P_C62117 Port 17 VLAN 1000 | R40: BZC_BCLBR_VBI_P_C62054 Port 5 | S40: GOD_BCLBR_PSG_P_C62117 Port 17 VLAN 1000 | U40: NA | V40: NA | W40: NA | X40: NA | Y40: NA | AA40: GTPL_GODBZC_10469 | AB40: 14292310 | AC40: 14156933 | AD40: Active
...

Sheet Lookup-Sheet
A1: Status | B1: BW | C1: CRQ | D1: AIRTEL Circuit ID | E1: Customer Name | F1: Location From | G1: Location To | H1: END A BTS ID | I1: END B BTS ID | J1: END A Port | K1: END B Port | L1: Provider | M1: Services
A2: =IF(OR(_xlfn.SINGLE('Lookup-Sheet'!$D:D) = "", ISNUMBER(SEARCH("CRQ",_xlfn.SINGLE(D:D )))), "",IFERROR(IFERROR(INDEX(B2B!$1:$1048576,MATCH(_xlfn.SINGLE('Lookup-Sheet'!$D:$D),B2B!$AD:$AD,0),MATCH(_xlfn.SINGLE('Lookup-Sheet'!$A$1:$M$1),B2B!$A$1:$AK$1,0)),INDEX('Link Shifting'!$1:$1048576,MATCH(_xlfn.SINGLE('Lookup-Sheet'!$D:$D),'Link Shifting'!$AC:$AC,0),MATCH(_xlfn.SINGLE('Lookup-Sheet'!$A$1:$M$1),'Link Shifting'!$A$1:$AD$1,0))), "No Data Found")) | B2: =IF(OR(_xlfn.SINGLE('Lookup-Sheet'!$D:D) = "", ISNUMBER(SEARCH("CRQ",_xlfn.SINGLE(D:D )))), "",IFERROR(IFERROR(INDEX(B2B!$1:$1048576,MATCH(_xlfn.SINGLE('Lookup-Sheet'!$D:$D),B2B!$AD:$AD,0),MATCH(_xlfn.SINGLE('Lookup-Sheet'!$A$1:$M$1),B2B!$A$1:$AK$1,0)),INDEX('Link Shifting'!$1:$1048576,MATCH(_xlfn.SINGLE('Lookup-Sheet'!$D:$D),'Link Shifting'!$AC:$AC,0),MATCH(_xlfn.SINGLE('Lookup-Sheet'!$A$1:$M$1),'Link Shifting'!$A$1:$AD$1,0))), "No Data Found")) | C2: =IF(D:D="","",IF(ISNUMBER(SEARCH("CRQ",D:D)),D:D,C1)) -> CRQ: 1100195255 (14-JAN) | D2: CRQ: 1100195255 (14-JAN) | E2: =IF(OR(_xlfn.SINGLE('Lookup-Sheet'!$D:D) = "", ISNUMBER(SEARCH("CRQ",_xlfn.SINGLE(D:D )))), "",IFERROR(IFERROR(INDEX(B2B!$1:$1048576,MATCH(_xlfn.SINGLE('Lookup-Sheet'!$D:$D),B2B!$AD:$AD,0),MATCH(_xlfn.SINGLE('Lookup-Sheet'!$A$1:$M$1),B2B!$A$1:$AK$1,0)),INDEX('Link Shifting'!$1:$1048576,MATCH(_xlfn.SINGLE('Lookup-Sheet'!$D:$D),'Link Shifting'!$AC:$AC,0),MATCH(_xlfn.SINGLE('Lookup-Sheet'!$A$1:$M$1),'Link Shifting'!$A$1:$AD$1,0))), "No Data Found")) | F2: =IF(OR(_xlfn.SINGLE('Lookup-Sheet'!$D:D) = "", ISNUMBER(SEARCH("CRQ",_xlfn.SINGLE(D:D )))), "",IFERROR(IFERROR(INDEX(B2B!$1:$1048576,MATCH(_xlfn.SINGLE('Lookup-Sheet'!$D:$D),B2B!$AD:$AD,0),MATCH(_xlfn.SINGLE('Lookup-Sheet'!$A$1:$M$1),B2B!$A$1:$AK$1,0)),INDEX('Link Shifting'!$1:$1048576,MATCH(_xlfn.SINGLE('Lookup-Sheet'!$D:$D),'Link Shifting'!$AC:$AC,0),MATCH(_xlfn.SINGLE('Lookup-Sheet'!$A$1:$M$1),'Link Shifting'!$A$1:$AD$1,0))), "No Data Found")) | G2: =IF(OR(_xlfn.SINGLE('Lookup-Sheet'!$D:D) = "", ISNUMBER(SEARCH("CRQ",_xlfn.SINGLE(D:D )))), "",IFERROR(IFERROR(INDEX(B2B!$1:$1048576,MATCH(_xlfn.SINGLE('Lookup-Sheet'!$D:$D),B2B!$AD:$AD,0),MATCH(_xlfn.SINGLE('Lookup-Sheet'!$A$1:$M$1),B2B!$A$1:$AK$1,0)),INDEX('Link Shifting'!$1:$1048576,MATCH(_xlfn.SINGLE('Lookup-Sheet'!$D:$D),'Link Shifting'!$AC:$AC,0),MATCH(_xlfn.SINGLE('Lookup-Sheet'!$A$1:$M$1),'Link Shifting'!$A$1:$AD$1,0))), "No Data Found")) | H2: =IF(OR(_xlfn.SINGLE('Lookup-Sheet'!$D:D) = "", ISNUMBER(SEARCH("CRQ",_xlfn.SINGLE(D:D )))), "",IFERROR(IFERROR(INDEX(B2B!$1:$1048576,MATCH(_xlfn.SINGLE('Lookup-Sheet'!$D:$D),B2B!$AD:$AD,0),MATCH(_xlfn.SINGLE('Lookup-Sheet'!$A$1:$M$1),B2B!$A$1:$AK$1,0)),INDEX('Link Shifting'!$1:$1048576,MATCH(_xlfn.SINGLE('Lookup-Sheet'!$D:$D),'Link Shifting'!$AC:$AC,0),MATCH(_xlfn.SINGLE('Lookup-Sheet'!$A$1:$M$1),'Link Shifting'!$A$1:$AD$1,0))), "No Data Found")) | I2: =IF(OR(_xlfn.SINGLE('Lookup-Sheet'!$D:D) = "", ISNUMBER(SEARCH("CRQ",_xlfn.SINGLE(D:D )))), "",IFERROR(IFERROR(INDEX(B2B!$1:$1048576,MATCH(_xlfn.SINGLE('Lookup-Sheet'!$D:$D),B2B!$AD:$AD,0),MATCH(_xlfn.SINGLE('Lookup-Sheet'!$A$1:$M$1),B2B!$A$1:$AK$1,0)),INDEX('Link Shifting'!$1:$1048576,MATCH(_xlfn.SINGLE('Lookup-Sheet'!$D:$D),'Link Shifting'!$AC:$AC,0),MATCH(_xlfn.SINGLE('Lookup-Sheet'!$A$1:$M$1),'Link Shifting'!$A$1:$AD$1,0))), "No Data Found")) | J2: =IF(OR(_xlfn.SINGLE('Lookup-Sheet'!$D:D) = "", ISNUMBER(SEARCH("CRQ",_xlfn.SINGLE(D:D )))), "",IFERROR(IFERROR(INDEX(B2B!$1:$1048576,MATCH(_xlfn.SINGLE('Lookup-Sheet'!$D:$D),B2B!$AD:$AD,0),MATCH(_xlfn.SINGLE('Lookup-Sheet'!$A$1:$M$1),B2B!$A$1:$AK$1,0)),INDEX('Link Shifting'!$1:$1048576,MATCH(_xlfn.SINGLE('Lookup-Sheet'!$D:$D),'Link Shifting'!$AC:$AC,0),MATCH(_xlfn.SINGLE('Lookup-Sheet'!$A$1:$M$1),'Link Shifting'!$A$1:$AD$1,0))), "No Data Found")) | K2: =IF(OR(_xlfn.SINGLE('Lookup-Sheet'!$D:D) = "", ISNUMBER(SEARCH("CRQ",_xlfn.SINGLE(D:D )))), "",IFERROR(IFERROR(INDEX(B2B!$1:$1048576,MATCH(_xlfn.SINGLE('Lookup-Sheet'!$D:$D),B2B!$AD:$AD,0),MATCH(_xlfn.SINGLE('Lookup-Sheet'!$A$1:$M$1),B2B!$A$1:$AK$1,0)),INDEX('Link Shifting'!$1:$1048576,MATCH(_xlfn.SINGLE('Lookup-Sheet'!$D:$D),'Link Shifting'!$AC:$AC,0),MATCH(_xlfn.SINGLE('Lookup-Sheet'!$A$1:$M$1),'Link Shifting'!$A$1:$AD$1,0))), "No Data Found")) | L2: =IF(OR(_xlfn.SINGLE('Lookup-Sheet'!$D:D) = "", ISNUMBER(SEARCH("CRQ",_xlfn.SINGLE(D:D )))), "",IFERROR(IFERROR(INDEX(B2B!$1:$1048576,MATCH(_xlfn.SINGLE('Lookup-Sheet'!$D:$D),B2B!$AD:$AD,0),MATCH(_xlfn.SINGLE('Lookup-Sheet'!$A$1:$M$1),B2B!$A$1:$AK$1,0)),INDEX('Link Shifting'!$1:$1048576,MATCH(_xlfn.SINGLE('Lookup-Sheet'!$D:$D),'Link Shifting'!$AC:$AC,0),MATCH(_xlfn.SINGLE('Lookup-Sheet'!$A$1:$M$1),'Link Shifting'!$A$1:$AD$1,0))), "No Data Found")) | M2: =IF(OR(_xlfn.SINGLE('Lookup-Sheet'!$D:D) = "", ISNUMBER(SEARCH("CRQ",_xlfn.SINGLE(D:D )))), "",IFERROR(IFERROR(INDEX(B2B!$1:$1048576,MATCH(_xlfn.SINGLE('Lookup-Sheet'!$D:$D),B2B!$AD:$AD,0),MATCH(_xlfn.SINGLE('Lookup-Sheet'!$A$1:$M$1),B2B!$A$1:$AK$1,0)),INDEX('Link Shifting'!$1:$1048576,MATCH(_xlfn.SINGLE('Lookup-Sheet'!$D:$D),'Link Shifting'!$AC:$AC,0),MATCH(_xlfn.SINGLE('Lookup-Sheet'!$A$1:$M$1),'Link Shifting'!$A$1:$AD$1,0))), "No Data Found"))
A3: =IF(OR(_xlfn.SINGLE('Lookup-Sheet'!$D:D) = "", ISNUMBER(SEARCH("CRQ",_xlfn.SINGLE(D:D )))), "",IFERROR(IFERROR(INDEX(B2B!$1:$1048576,MATCH(_xlfn.SINGLE('Lookup-Sheet'!$D:$D),B2B!$AD:$AD,0),MATCH(_xlfn.SINGLE('Lookup-Sheet'!$A$1:$M$1),B2B!$A$1:$AK$1,0)),INDEX('Link Shifting'!$1:$1048576,MATCH(_xlfn.SINGLE('Lookup-Sheet'!$D:$D),'Link Shifting'!$AC:$AC,0),MATCH(_xlfn.SINGLE('Lookup-Sheet'!$A$1:$M$1),'Link Shifting'!$A$1:$AD$1,0))), "No Data Found")) -> Active | B3: =IF(OR(_xlfn.SINGLE('Lookup-Sheet'!$D:D) = "", ISNUMBER(SEARCH("CRQ",_xlfn.SINGLE(D:D )))), "",IFERROR(IFERROR(INDEX(B2B!$1:$1048576,MATCH(_xlfn.SINGLE('Lookup-Sheet'!$D:$D),B2B!$AD:$AD,0),MATCH(_xlfn.SINGLE('Lookup-Sheet'!$A$1:$M$1),B2B!$A$1:$AK$1,0)),INDEX('Link Shifting'!$1:$1048576,MATCH(_xlfn.SINGLE('Lookup-Sheet'!$D:$D),'Link Shifting'!$AC:$AC,0),MATCH(_xlfn.SINGLE('Lookup-Sheet'!$A$1:$M$1),'Link Shifting'!$A$1:$AD$1,0))), "No Data Found")) -> 512 | C3: =IF(D:D="","",IF(ISNUMBER(SEARCH("CRQ",D:D)),D:D,C2)) -> CRQ: 1100195255 (14-JAN) | D3: 14306424 | E3: =IF(OR(_xlfn.SINGLE('Lookup-Sheet'!$D:D) = "", ISNUMBER(SEARCH("CRQ",_xlfn.SINGLE(D:D )))), "",IFERROR(IFERROR(INDEX(B2B!$1:$1048576,MATCH(_xlfn.SINGLE('Lookup-Sheet'!$D:$D),B2B!$AD:$AD,0),MATCH(_xlfn.SINGLE('Lookup-Sheet'!$A$1:$M$1),B2B!$A$1:$AK$1,0)),INDEX('Link Shifting'!$1:$1048576,MATCH(_xlfn.SINGLE('Lookup-Sheet'!$D:$D),'Link Shifting'!$AC:$AC,0),MATCH(_xlfn.SINGLE('Lookup-Sheet'!$A$1:$M$1),'Link Shifting'!$A$1:$AD$1,0))), "No Data Found")) -> Vision Hi-Speed Technology Pvt. Ltd | F3: =IF(OR(_xlfn.SINGLE('Lookup-Sheet'!$D:D) = "", ISNUMBER(SEARCH("CRQ",_xlfn.SINGLE(D:D )))), "",IFERROR(IFERROR(INDEX(B2B!$1:$1048576,MATCH(_xlfn.SINGLE('Lookup-Sheet'!$D:$D),B2B!$AD:$AD,0),MATCH(_xlfn.SINGLE('Lookup-Sheet'!$A$1:$M$1),B2B!$A$1:$AK$1,0)),INDEX('Link Shifting'!$1:$1048576,MATCH(_xlfn.SINGLE('Lookup-Sheet'!$D:$D),'Link Shifting'!$AC:$AC,0),MATCH(_xlfn.SINGLE('Lookup-Sheet'!$A$1:$M$1),'Link Shifting'!$A$1:$AD$1,0))), "No Data Found")) -> NA | G3: =IF(OR(_xlfn.SINGLE('Lookup-Sheet'!$D:D) = "", ISNUMBER(SEARCH("CRQ",_xlfn.SINGLE(D:D )))), "",IFERROR(IFERROR(INDEX(B2B!$1:$1048576,MATCH(_xlfn.SINGLE('Lookup-Sheet'!$D:$D),B2B!$AD:$AD,0),MATCH(_xlfn.SINGLE('Lookup-Sheet'!$A$1:$M$1),B2B!$A$1:$AK$1,0)),INDEX('Link Shifting'!$1:$1048576,MATCH(_xlfn.SINGLE('Lookup-Sheet'!$D:$D),'Link Shifting'!$AC:$AC,0),MATCH(_xlfn.SINGLE('Lookup-Sheet'!$A$1:$M$1),'Link Shifting'!$A$1:$AD$1,0))), "No Data Found")) -> Rajkot | H3: =IF(OR(_xlfn.SINGLE('Lookup-Sheet'!$D:D) = "", ISNUMBER(SEARCH("CRQ",_xlfn.SINGLE(D:D )))), "",IFERROR(IFERROR(INDEX(B2B!$1:$1048576,MATCH(_xlfn.SINGLE('Lookup-Sheet'!$D:$D),B2B!$AD:$AD,0),MATCH(_xlfn.SINGLE('Lookup-Sheet'!$A$1:$M$1),B2B!$A$1:$AK$1,0)),INDEX('Link Shifting'!$1:$1048576,MATCH(_xlfn.SINGLE('Lookup-Sheet'!$D:$D),'Link Shifting'!$AC:$AC,0),MATCH(_xlfn.SINGLE('Lookup-Sheet'!$A$1:$M$1),'Link Shifting'!$A$1:$AD$1,0))), "No Data Found")) -> NA | I3: =IF(OR(_xlfn.SINGLE('Lookup-Sheet'!$D:D) = "", ISNUMBER(SEARCH("CRQ",_xlfn.SINGLE(D:D )))), "",IFERROR(IFERROR(INDEX(B2B!$1:$1048576,MATCH(_xlfn.SINGLE('Lookup-Sheet'!$D:$D),B2B!$AD:$AD,0),MATCH(_xlfn.SINGLE('Lookup-Sheet'!$A$1:$M$1),B2B!$A$1:$AK$1,0)),INDEX('Link Shifting'!$1:$1048576,MATCH(_xlfn.SINGLE('Lookup-Sheet'!$D:$D),'Link Shifting'!$AC:$AC,0),MATCH(_xlfn.SINGLE('Lookup-Sheet'!$A$1:$M$1),'Link Shifting'!$A$1:$AD$1,0))), "No Data Found")) -> RKT/RPI/050 | J3: =IF(OR(_xlfn.SINGLE('Lookup-Sheet'!$D:D) = "", ISNUMBER(SEARCH("CRQ",_xlfn.SINGLE(D:D )))), "",IFERROR(IFERROR(INDEX(B2B!$1:$1048576,MATCH(_xlfn.SINGLE('Lookup-Sheet'!$D:$D),B2B!$AD:$AD,0),MATCH(_xlfn.SINGLE('Lookup-Sheet'!$A$1:$M$1),B2B!$A$1:$AK$1,0)),INDEX('Link Shifting'!$1:$1048576,MATCH(_xlfn.SINGLE('Lookup-Sheet'!$D:$D),'Link Shifting'!$AC:$AC,0),MATCH(_xlfn.SINGLE('Lookup-Sheet'!$A$1:$M$1),'Link Shifting'!$A$1:$AD$1,0))), "No Data Found")) -> NA | K3: =IF(OR(_xlfn.SINGLE('Lookup-Sheet'!$D:D) = "", ISNUMBER(SEARCH("CRQ",_xlfn.SINGLE(D:D )))), "",IFERROR(IFERROR(INDEX(B2B!$1:$1048576,MATCH(_xlfn.SINGLE('Lookup-Sheet'!$D:$D),B2B!$AD:$AD,0),MATCH(_xlfn.SINGLE('Lookup-Sheet'!$A$1:$M$1),B2B!$A$1:$AK$1,0)),INDEX('Link Shifting'!$1:$1048576,MATCH(_xlfn.SINGLE('Lookup-Sheet'!$D:$D),'Link Shifting'!$AC:$AC,0),MATCH(_xlfn.SINGLE('Lookup-Sheet'!$A$1:$M$1),'Link Shifting'!$A$1:$AD$1,0))), "No Data Found")) -> RKT-BCLGJ-RPI-T5-ER18.86 TS2-1 | L3: =IF(OR(_xlfn.SINGLE('Lookup-Sheet'!$D:D) = "", ISNUMBER(SEARCH("CRQ",_xlfn.SINGLE(D:D )))), "",IFERROR(IFERROR(INDEX(B2B!$1:$1048576,MATCH(_xlfn.SINGLE('Lookup-Sheet'!$D:$D),B2B!$AD:$AD,0),MATCH(_xlfn.SINGLE('Lookup-Sheet'!$A$1:$M$1),B2B!$A$1:$AK$1,0)),INDEX('Link Shifting'!$1:$1048576,MATCH(_xlfn.SINGLE('Lookup-Sheet'!$D:$D),'Link Shifting'!$AC:$AC,0),MATCH(_xlfn.SINGLE('Lookup-Sheet'!$A$1:$M$1),'Link Shifting'!$A$1:$AD$1,0))), "No Data Found")) -> Airtel | M3: =IF(OR(_xlfn.SINGLE('Lookup-Sheet'!$D:D) = "", ISNUMBER(SEARCH("CRQ",_xlfn.SINGLE(D:D )))), "",IFERROR(IFERROR(INDEX(B2B!$1:$1048576,MATCH(_xlfn.SINGLE('Lookup-Sheet'!$D:$D),B2B!$AD:$AD,0),MATCH(_xlfn.SINGLE('Lookup-Sheet'!$A$1:$M$1),B2B!$A$1:$AK$1,0)),INDEX('Link Shifting'!$1:$1048576,MATCH(_xlfn.SINGLE('Lookup-Sheet'!$D:$D),'Link Shifting'!$AC:$AC,0),MATCH(_xlfn.SINGLE('Lookup-Sheet'!$A$1:$M$1),'Link Shifting'!$A$1:$AD$1,0))), "No Data Found")) -> ILL
A4: =IF(OR(_xlfn.SINGLE('Lookup-Sheet'!$D:D) = "", ISNUMBER(SEARCH("CRQ",_xlfn.SINGLE(D:D )))), "",IFERROR(IFERROR(INDEX(B2B!$1:$1048576,MATCH(_xlfn.SINGLE('Lookup-Sheet'!$D:$D),B2B!$AD:$AD,0),MATCH(_xlfn.SINGLE('Lookup-Sheet'!$A$1:$M$1),B2B!$A$1:$AK$1,0)),INDEX('Link Shifting'!$1:$1048576,MATCH(_xlfn.SINGLE('Lookup-Sheet'!$D:$D),'Link Shifting'!$AC:$AC,0),MATCH(_xlfn.SINGLE('Lookup-Sheet'!$A$1:$M$1),'Link Shifting'!$A$1:$AD$1,0))), "No Data Found")) -> Active | B4: =IF(OR(_xlfn.SINGLE('Lookup-Sheet'!$D:D) = "", ISNUMBER(SEARCH("CRQ",_xlfn.SINGLE(D:D )))), "",IFERROR(IFERROR(INDEX(B2B!$1:$1048576,MATCH(_xlfn.SINGLE('Lookup-Sheet'!$D:$D),B2B!$AD:$AD,0),MATCH(_xlfn.SINGLE('Lookup-Sheet'!$A$1:$M$1),B2B!$A$1:$AK$1,0)),INDEX('Link Shifting'!$1:$1048576,MATCH(_xlfn.SINGLE('Lookup-Sheet'!$D:$D),'Link Shifting'!$AC:$AC,0),MATCH(_xlfn.SINGLE('Lookup-Sheet'!$A$1:$M$1),'Link Shifting'!$A$1:$AD$1,0))), "No Data Found")) -> 300 | C4: =IF(D:D="","",IF(ISNUMBER(SEARCH("CRQ",D:D)),D:D,C3)) -> CRQ: 1100195255 (14-JAN) | D4: 14030127 | E4: =IF(OR(_xlfn.SINGLE('Lookup-Sheet'!$D:D) = "", ISNUMBER(SEARCH("CRQ",_xlfn.SINGLE(D:D )))), "",IFERROR(IFERROR(INDEX(B2B!$1:$1048576,MATCH(_xlfn.SINGLE('Lookup-Sheet'!$D:$D),B2B!$AD:$AD,0),MATCH(_xlfn.SINGLE('Lookup-Sheet'!$A$1:$M$1),B2B!$A$1:$AK$1,0)),INDEX('Link Shifting'!$1:$1048576,MATCH(_xlfn.SINGLE('Lookup-Sheet'!$D:$D),'Link Shifting'!$AC:$AC,0),MATCH(_xlfn.SINGLE('Lookup-Sheet'!$A$1:$M$1),'Link Shifting'!$A$1:$AD$1,0))), "No Data Found")) -> SKYONLINE TECHNOSYSTEM PRIVATE LIMITED | F4: =IF(OR(_xlfn.SINGLE('Lookup-Sheet'!$D:D) = "", ISNUMBER(SEARCH("CRQ",_xlfn.SINGLE(D:D )))), "",IFERROR(IFERROR(INDEX(B2B!$1:$1048576,MATCH(_xlfn.SINGLE('Lookup-Sheet'!$D:$D),B2B!$AD:$AD,0),MATCH(_xlfn.SINGLE('Lookup-Sheet'!$A$1:$M$1),B2B!$A$1:$AK$1,0)),INDEX('Link Shifting'!$1:$1048576,MATCH(_xlfn.SINGLE('Lookup-Sheet'!$D:$D),'Link Shifting'!$AC:$AC,0),MATCH(_xlfn.SINGLE('Lookup-Sheet'!$A$1:$M$1),'Link Shifting'!$A$1:$AD$1,0))), "No Data Found")) -> NA | G4: =IF(OR(_xlfn.SINGLE('Lookup-Sheet'!$D:D) = "", ISNUMBER(SEARCH("CRQ",_xlfn.SINGLE(D:D )))), "",IFERROR(IFERROR(INDEX(B2B!$1:$1048576,MATCH(_xlfn.SINGLE('Lookup-Sheet'!$D:$D),B2B!$AD:$AD,0),MATCH(_xlfn.SINGLE('Lookup-Sheet'!$A$1:$M$1),B2B!$A$1:$AK$1,0)),INDEX('Link Shifting'!$1:$1048576,MATCH(_xlfn.SINGLE('Lookup-Sheet'!$D:$D),'Link Shifting'!$AC:$AC,0),MATCH(_xlfn.SINGLE('Lookup-Sheet'!$A$1:$M$1),'Link Shifting'!$A$1:$AD$1,0))), "No Data Found")) -> Rajkot | H4: =IF(OR(_xlfn.SINGLE('Lookup-Sheet'!$D:D) = "", ISNUMBER(SEARCH("CRQ",_xlfn.SINGLE(D:D )))), "",IFERROR(IFERROR(INDEX(B2B!$1:$1048576,MATCH(_xlfn.SINGLE('Lookup-Sheet'!$D:$D),B2B!$AD:$AD,0),MATCH(_xlfn.SINGLE('Lookup-Sheet'!$A$1:$M$1),B2B!$A$1:$AK$1,0)),INDEX('Link Shifting'!$1:$1048576,MATCH(_xlfn.SINGLE('Lookup-Sheet'!$D:$D),'Link Shifting'!$AC:$AC,0),MATCH(_xlfn.SINGLE('Lookup-Sheet'!$A$1:$M$1),'Link Shifting'!$A$1:$AD$1,0))), "No Data Found")) -> NA | I4: =IF(OR(_xlfn.SINGLE('Lookup-Sheet'!$D:D) = "", ISNUMBER(SEARCH("CRQ",_xlfn.SINGLE(D:D )))), "",IFERROR(IFERROR(INDEX(B2B!$1:$1048576,MATCH(_xlfn.SINGLE('Lookup-Sheet'!$D:$D),B2B!$AD:$AD,0),MATCH(_xlfn.SINGLE('Lookup-Sheet'!$A$1:$M$1),B2B!$A$1:$AK$1,0)),INDEX('Link Shifting'!$1:$1048576,MATCH(_xlfn.SINGLE('Lookup-Sheet'!$D:$D),'Link Shifting'!$AC:$AC,0),MATCH(_xlfn.SINGLE('Lookup-Sheet'!$A$1:$M$1),'Link Shifting'!$A$1:$AD$1,0))), "No Data Found")) -> RKT/SSN/063 | J4: =IF(OR(_xlfn.SINGLE('Lookup-Sheet'!$D:D) = "", ISNUMBER(SEARCH("CRQ",_xlfn.SINGLE(D:D )))), "",IFERROR(IFERROR(INDEX(B2B!$1:$1048576,MATCH(_xlfn.SINGLE('Lookup-Sheet'!$D:$D),B2B!$AD:$AD,0),MATCH(_xlfn.SINGLE('Lookup-Sheet'!$A$1:$M$1),B2B!$A$1:$AK$1,0)),INDEX('Link Shifting'!$1:$1048576,MATCH(_xlfn.SINGLE('Lookup-Sheet'!$D:$D),'Link Shifting'!$AC:$AC,0),MATCH(_xlfn.SINGLE('Lookup-Sheet'!$A$1:$M$1),'Link Shifting'!$A$1:$AD$1,0))), "No Data Found")) -> NA | K4: =IF(OR(_xlfn.SINGLE('Lookup-Sheet'!$D:D) = "", ISNUMBER(SEARCH("CRQ",_xlfn.SINGLE(D:D )))), "",IFERROR(IFERROR(INDEX(B2B!$1:$1048576,MATCH(_xlfn.SINGLE('Lookup-Sheet'!$D:$D),B2B!$AD:$AD,0),MATCH(_xlfn.SINGLE('Lookup-Sheet'!$A$1:$M$1),B2B!$A$1:$AK$1,0)),INDEX('Link Shifting'!$1:$1048576,MATCH(_xlfn.SINGLE('Lookup-Sheet'!$D:$D),'Link Shifting'!$AC:$AC,0),MATCH(_xlfn.SINGLE('Lookup-Sheet'!$A$1:$M$1),'Link Shifting'!$A$1:$AD$1,0))), "No Data Found")) -> RKT_BCLGJ_SSN_P_E56776 TS7-4 | L4: =IF(OR(_xlfn.SINGLE('Lookup-Sheet'!$D:D) = "", ISNUMBER(SEARCH("CRQ",_xlfn.SINGLE(D:D )))), "",IFERROR(IFERROR(INDEX(B2B!$1:$1048576,MATCH(_xlfn.SINGLE('Lookup-Sheet'!$D:$D),B2B!$AD:$AD,0),MATCH(_xlfn.SINGLE('Lookup-Sheet'!$A$1:$M$1),B2B!$A$1:$AK$1,0)),INDEX('Link Shifting'!$1:$1048576,MATCH(_xlfn.SINGLE('Lookup-Sheet'!$D:$D),'Link Shifting'!$AC:$AC,0),MATCH(_xlfn.SINGLE('Lookup-Sheet'!$A$1:$M$1),'Link Shifting'!$A$1:$AD$1,0))), "No Data Found")) -> Airtel | M4: =IF(OR(_xlfn.SINGLE('Lookup-Sheet'!$D:D) = "", ISNUMBER(SEARCH("CRQ",_xlfn.SINGLE(D:D )))), "",IFERROR(IFERROR(INDEX(B2B!$1:$1048576,MATCH(_xlfn.SINGLE('Lookup-Sheet'!$D:$D),B2B!$AD:$AD,0),MATCH(_xlfn.SINGLE('Lookup-Sheet'!$A$1:$M$1),B2B!$A$1:$AK$1,0)),INDEX('Link Shifting'!$1:$1048576,MATCH(_xlfn.SINGLE('Lookup-Sheet'!$D:$D),'Link Shifting'!$AC:$AC,0),MATCH(_xlfn.SINGLE('Lookup-Sheet'!$A$1:$M$1),'Link Shifting'!$A$1:$AD$1,0))), "No Data Found")) -> ILL
